<?xml version="1.0" ?>
<robot name="corrado" xmlns:xacro="http://www.ros.org/wiki/xacro">

<xacro:include filename="$(find corrado_description)/urdf/materials.xacro" />
<xacro:include filename="$(find corrado_description)/urdf/corrado.trans" />
<xacro:include filename="$(find corrado_description)/urdf/corrado.gazebo" />

<link name="base_link">
  <inertial>
    <origin xyz="0.0 0.0 0.0" rpy="0 0 0"/>
    <mass value="0.25589656457731824"/>
    <inertia ixx="0.000372" iyy="0.000376" izz="0.000587" ixy="-2e-06" iyz="2e-06" ixz="-1e-06"/>
  </inertial>
  <visual>
    <origin xyz="0 0 0" rpy="0 0 0"/>
    <geometry>
      <mesh filename="package://corrado_description/meshes/base_link.stl" scale="0.001 0.001 0.001"/>
    </geometry>
    <material name="silver"/>
  </visual>
  <collision>
    <origin xyz="0 0 0" rpy="0 0 0"/>
    <geometry>
      <mesh filename="package://corrado_description/meshes/base_link.stl" scale="0.001 0.001 0.001"/>
    </geometry>
  </collision>
</link>

<link name="link_1">
  <inertial>
    <origin xyz="0.00352082327625453 -0.0018186197347480016 0.0259398092692686" rpy="0 0 0"/>
    <mass value="0.21815052421722608"/>
    <inertia ixx="0.000187" iyy="0.000231" izz="0.000255" ixy="-2.5e-05" iyz="-9e-06" ixz="-1.2e-05"/>
  </inertial>
  <visual>
    <origin xyz="0.0001 -0.0005 -0.05587" rpy="0 0 0"/>
    <geometry>
      <mesh filename="package://corrado_description/meshes/link_1.stl" scale="0.001 0.001 0.001"/>
    </geometry>
    <material name="silver"/>
  </visual>
  <collision>
    <origin xyz="0.0001 -0.0005 -0.05587" rpy="0 0 0"/>
    <geometry>
      <mesh filename="package://corrado_description/meshes/link_1.stl" scale="0.001 0.001 0.001"/>
    </geometry>
  </collision>
</link>

<link name="link_2">
  <inertial>
    <origin xyz="0.0001846008097610534 -0.014049470109742461 0.042991728047063485" rpy="0 0 0"/>
    <mass value="0.06723503488021657"/>
    <inertia ixx="0.00015" iyy="0.000136" izz="2.1e-05" ixy="5e-06" iyz="3.7e-05" ixz="-1.1e-05"/>
  </inertial>
  <visual>
    <origin xyz="-0.016576 -0.026157 -0.11608" rpy="0 0 0"/>
    <geometry>
      <mesh filename="package://corrado_description/meshes/link_2.stl" scale="0.001 0.001 0.001"/>
    </geometry>
    <material name="silver"/>
  </visual>
  <collision>
    <origin xyz="-0.016576 -0.026157 -0.11608" rpy="0 0 0"/>
    <geometry>
      <mesh filename="package://corrado_description/meshes/link_2.stl" scale="0.001 0.001 0.001"/>
    </geometry>
  </collision>
</link>

<link name="link_3">
  <inertial>
    <origin xyz="-0.007224003713249013 -0.020580489284341474 0.03421444612653318" rpy="0 0 0"/>
    <mass value="0.07088669177132391"/>
    <inertia ixx="5.2e-05" iyy="4e-05" izz="4.4e-05" ixy="3e-06" iyz="3e-06" ixz="1e-06"/>
  </inertial>
  <visual>
    <origin xyz="-0.018006 0.010969 -0.230813" rpy="0 0 0"/>
    <geometry>
      <mesh filename="package://corrado_description/meshes/link_3.stl" scale="0.001 0.001 0.001"/>
    </geometry>
    <material name="silver"/>
  </visual>
  <collision>
    <origin xyz="-0.018006 0.010969 -0.230813" rpy="0 0 0"/>
    <geometry>
      <mesh filename="package://corrado_description/meshes/link_3.stl" scale="0.001 0.001 0.001"/>
    </geometry>
  </collision>
</link>

<link name="link_4">
  <inertial>
    <origin xyz="-0.01659573639655563 0.05258774665278596 0.019176336133320537" rpy="0 0 0"/>
    <mass value="0.16607850247781106"/>
    <inertia ixx="0.000297" iyy="8.1e-05" izz="0.000315" ixy="4.1e-05" iyz="-6.8e-05" ixz="1.4e-05"/>
  </inertial>
  <visual>
    <origin xyz="-0.004135 0.009249 -0.277401" rpy="0 0 0"/>
    <geometry>
      <mesh filename="package://corrado_description/meshes/link_4.stl" scale="0.001 0.001 0.001"/>
    </geometry>
    <material name="silver"/>
  </visual>
  <collision>
    <origin xyz="-0.004135 0.009249 -0.277401" rpy="0 0 0"/>
    <geometry>
      <mesh filename="package://corrado_description/meshes/link_4.stl" scale="0.001 0.001 0.001"/>
    </geometry>
  </collision>
</link>

<link name="link_5">
  <inertial>
    <origin xyz="-0.027690434752053836 0.0032080443245588453 0.004011085602064979" rpy="0 0 0"/>
    <mass value="0.033622009165911515"/>
    <inertia ixx="1.5e-05" iyy="1.1e-05" izz="1.8e-05" ixy="2e-06" iyz="-2e-06" ixz="1e-06"/>
  </inertial>
  <visual>
    <origin xyz="0.025004 -0.133398 -0.321307" rpy="0 0 0"/>
    <geometry>
      <mesh filename="package://corrado_description/meshes/link_5.stl" scale="0.001 0.001 0.001"/>
    </geometry>
    <material name="silver"/>
  </visual>
  <collision>
    <origin xyz="0.025004 -0.133398 -0.321307" rpy="0 0 0"/>
    <geometry>
      <mesh filename="package://corrado_description/meshes/link_5.stl" scale="0.001 0.001 0.001"/>
    </geometry>
  </collision>
</link>

<link name="end_effector">
  <inertial>
    <origin xyz="-0.0065736845500056346 0.016754005066701466 0.005502828670762017" rpy="0 0 0"/>
    <mass value="0.14259404167762188"/>
    <inertia ixx="5e-05" iyy="3e-05" izz="5.7e-05" ixy="9e-06" iyz="-1e-05" ixz="4e-06"/>
  </inertial>
  <visual>
    <origin xyz="0.061559 -0.158102 -0.332372" rpy="0 0 0"/>
    <geometry>
      <mesh filename="package://corrado_description/meshes/end_effector.stl" scale="0.001 0.001 0.001"/>
    </geometry>
    <material name="silver"/>
  </visual>
  <collision>
    <origin xyz="0.061559 -0.158102 -0.332372" rpy="0 0 0"/>
    <geometry>
      <mesh filename="package://corrado_description/meshes/end_effector.stl" scale="0.001 0.001 0.001"/>
    </geometry>
  </collision>
</link>

<joint name="joint_1" type="revolute">
  <origin xyz="-0.0001 0.0005 0.05587" rpy="0 0 0"/>
  <parent link="base_link"/>
  <child link="link_1"/>
  <axis xyz="-0.001737 -0.000686 0.999998"/>
  <limit effort="14" velocity="0.5" lower="-1.57" upper="1.57"/>
</joint>

<joint name="joint_2" type="revolute">
  <origin xyz="0.016676 0.025657 0.06021" rpy="0 0 0"/>
  <parent link="link_1"/>
  <child link="link_2"/>
  <axis xyz="-0.931054 -0.364876 -0.001868"/>
  <limit effort="14" velocity="0.5" lower="-1.57" upper="1.57"/>
</joint>

<joint name="joint_3" type="revolute">
  <origin xyz="0.00143 -0.037126 0.114733" rpy="0 0 0"/>
  <parent link="link_2"/>
  <child link="link_3"/>
  <axis xyz="-0.931054 -0.364876 -0.001868"/>
  <limit effort="14" velocity="0.5" lower="-1.57" upper="1.57"/>
</joint>

<joint name="joint_4" type="revolute">
  <origin xyz="-0.013871 0.00172 0.046588" rpy="0 0 0"/>
  <parent link="link_3"/>
  <child link="link_4"/>
  <axis xyz="-0.349438 0.890166 0.292399"/>
  <limit effort="14" velocity="0.5" lower="-1.57" upper="1.57"/>
</joint>

<joint name="joint_5" type="revolute">
  <origin xyz="-0.029139 0.142647 0.043906" rpy="0 0 0"/>
  <parent link="link_4"/>
  <child link="link_5"/>
  <axis xyz="0.931054 0.364876 0.001868"/>
  <limit effort="14" velocity="0.5" lower="-1.57" upper="1.57"/>
</joint>

<joint name="joint_6" type="revolute">
  <origin xyz="-0.036555 0.024704 0.011065" rpy="0 0 0"/>
  <parent link="link_5"/>
  <child link="end_effector"/>
  <axis xyz="-0.349438 0.890166 0.292399"/>
  <limit effort="14" velocity="0.5" lower="-1.57" upper="1.57"/>
</joint>

</robot>
